Workbook
Name DaySpec: Fields!$B$14
Name DirSpec: Fields!$C$16
Name EndDate: Fields!$C$12
Name FieldSpec: Fields!$C$10
Name FillSpec: Fields!$C$15
Name InstrumentSpec: Fields!$B$9
Name PeriodSpec: Fields!$B$13
Name StartDate: Fields!$B$11

Sheet Fields
A2: Postfix | C2: 1Y | E2: 5Y | G2: 10Y | I2: Test Names | O2: Test Field
A3: R | B3: GTTRY | C3: =$B3&C$2&$A3&" Govt" -> GTTRY1YR Govt | E3: =$B3&E$2&$A3&" Govt" -> GTTRY5YR Govt | G3: =$B3&G$2&" Govt" -> GTTRY10Y Govt | I3: {=_xll.BDP(C3,"NAME")} -> TURKIYE GOVERNMENT BOND | J3: {=_xll.BDP(E3,"NAME")} -> TURKIYE GOVERNMENT BOND | K3: {=_xll.BDP(G3,"NAME")} -> TURKIYE GOVERNMENT BOND | O3: {=_xll.BDP(C3,FieldSpec)} -> 33.25 | P3: {=_xll.BDP(E3,FieldSpec)} -> 30.78 | Q3: {=_xll.BDP(G3,FieldSpec)} -> 28.16 | S3: {=ISERROR(_xll.BDH(C3,FieldSpec,StartDate,EndDate))} -> FALSE | T3: {=ISERROR(_xll.BDH(E3,FieldSpec,StartDate,EndDate))} -> FALSE | U3: {=ISERROR(_xll.BDH(G3,FieldSpec,StartDate,EndDate))} -> FALSE
A4: R | B4: GTNGN | C4: =$B4&C$2&$A4&" Govt" -> GTNGN1YR Govt | E4: =$B4&E$2&$A4&" Govt" -> GTNGN5YR Govt | G4: =$B4&G$2&" Govt" -> GTNGN10Y Govt | I4: {=_xll.BDP(C4,"NAME")} -> NIGERIA T-BILL | J4: {=_xll.BDP(E4,"NAME")} -> NIGERIA GOVERNMENT BOND | K4: {=_xll.BDP(G4,"NAME")} -> NIGERIA GOVERNMENT BOND | O4: {=_xll.BDP(C4,FieldSpec)} -> 19.168619 | P4: {=_xll.BDP(E4,FieldSpec)} -> 16.1491 | Q4: {=_xll.BDP(G4,FieldSpec)} -> 16.5456 | S4: {=ISERROR(_xll.BDH(C4,FieldSpec,StartDate,EndDate))} -> FALSE | T4: {=ISERROR(_xll.BDH(E4,FieldSpec,StartDate,EndDate))} -> FALSE | U4: {=ISERROR(_xll.BDH(G4,FieldSpec,StartDate,EndDate))} -> FALSE
B5: GTPKR | C5: =$B5&C$2&$A5&" Govt" -> GTPKR1Y Govt | E5: =$B5&E$2&$A5&" Govt" -> GTPKR5Y Govt | G5: =$B5&G$2&$A5&" Govt" -> GTPKR10Y Govt | I5: {=_xll.BDP(C5,"NAME")} -> PAKISTAN T-BILL | J5: {=_xll.BDP(E5,"NAME")} -> PAKISTAN INVESTMENT BOND | K5: {=_xll.BDP(G5,"NAME")} -> PAKISTAN INVESTMENT BOND | O5: {=_xll.BDP(C5,FieldSpec)} -> 10.3667 | P5: {=_xll.BDP(E5,FieldSpec)} -> 11.053152 | Q5: {=_xll.BDP(G5,FieldSpec)} -> 11.305247 | S5: {=ISERROR(_xll.BDH(C5,FieldSpec,StartDate,EndDate))} -> FALSE | T5: {=ISERROR(_xll.BDH(E5,FieldSpec,StartDate,EndDate))} -> FALSE | U5: {=ISERROR(_xll.BDH(G5,FieldSpec,StartDate,EndDate))} -> FALSE
A6: R | B6: GTZAR | C6: =$B6&C$2&$A6&" Govt" -> GTZAR1YR Govt | E6: =$B6&E$2&$A6&" Govt" -> GTZAR5YR Govt | G6: =$B6&G$2&" Govt" -> GTZAR10Y Govt | I6: {=_xll.BDP(C6,"NAME")} -> SOUTH AFRICAN T-BILLS | J6: {=_xll.BDP(E6,"NAME")} -> REPUBLIC OF SOUTH AFRICA | K6: {=_xll.BDP(G6,"NAME")} -> REPUBLIC OF SOUTH AFRICA | O6: {=_xll.BDP(C6,FieldSpec)} -> 6.9739384 | P6: {=_xll.BDP(E6,FieldSpec)} -> 7.139 | Q6: {=_xll.BDP(G6,FieldSpec)} -> 7.966 | S6: {=ISERROR(_xll.BDH(C6,FieldSpec,StartDate,EndDate))} -> FALSE | T6: {=ISERROR(_xll.BDH(E6,FieldSpec,StartDate,EndDate))} -> FALSE | U6: {=ISERROR(_xll.BDH(G6,FieldSpec,StartDate,EndDate))} -> FALSE
B7: GTBRL | C7: =$B7&C$2&$A7&" Govt" -> GTBRL1Y Govt | E7: =$B7&E$2&$A7&" Govt" -> GTBRL5Y Govt | G7: =$B7&G$2&" Govt" -> GTBRL10Y Govt | I7: {=_xll.BDP(C7,"NAME")} -> LETRA TESOURO NACIONAL | J7: {=_xll.BDP(E7,"NAME")} -> NOTA DO TESOURO NACIONAL | K7: {=_xll.BDP(G7,"NAME")} -> NOTA DO TESOURO NACIONAL | O7: {=_xll.BDP(C7,FieldSpec)} -> 13.0474 | P7: {=_xll.BDP(E7,FieldSpec)} -> 13.3461 | Q7: {=_xll.BDP(G7,FieldSpec)} -> 13.7259 | S7: {=ISERROR(_xll.BDH(C7,FieldSpec,StartDate,EndDate))} -> FALSE | T7: {=ISERROR(_xll.BDH(E7,FieldSpec,StartDate,EndDate))} -> FALSE | U7: {=ISERROR(_xll.BDH(G7,FieldSpec,StartDate,EndDate))} -> FALSE
B9: Bberg string | C9: =_xlfn.TEXTJOIN(", ",TRUE,C3:G7) -> GTTRY1YR Govt, GTTRY5YR Govt, GTTRY10Y Govt, GTNGN1YR Govt, GTNGN5YR Govt, GTNGN10Y Govt, GTPKR1Y Govt, GTPKR5Y Govt, GTPKR10Y Govt, GTZAR1YR Govt, GTZAR5YR Govt, GTZAR10Y Govt, GTBRL1Y Govt, GTBRL5Y Govt, GTBRL10Y Govt
B10: Bberg Field | C10: YLD_YTM_BID
B11: Start Date | C11: 43466
B12: End Date | C12: 46064
B13: Periodicty Spec | C13: Per=W
B14: Day Of Week Spec | C14: Day=W
B15: Fill Spec | C15: Fill=P
B16: Dir Spec | C16: Dir=H

Sheet Row 1
A1: =Fields!C3 -> GTTRY1YR Govt | C1: =Fields!E3 -> GTTRY5YR Govt | E1: =Fields!G3 -> GTTRY10Y Govt
A2: {=_xll.BDH(A1,FieldSpec,"1/1/2019","1/1/2026")} -> 43468 | B2: 21.53 | C2: {=_xll.BDH(C1,FieldSpec,"1/1/2019","1/1/2026")} -> 43810 | D2: 11.99 | E2: {=_xll.BDH(E1,FieldSpec,"1/1/2019","1/1/2026")} -> 43552 | F2: 18.37
A3: 43469 | B3: 21.71 | C3: 43811 | D3: 11.82 | E3: 43553 | F3: 17.26
A4: 43472 | B4: 21.81 | C4: 43812 | D4: 11.82 | E4: 43556 | F4: 17
A5: 43473 | B5: 21.77 | C5: 43815 | D5: 12 | E5: 43557 | F5: 17.23
A6: 43474 | B6: 21.91 | C6: 43816 | D6: 12.04 | E6: 43558 | F6: 17.1
A7: 43475 | B7: 21.79 | C7: 43817 | D7: 12.18 | E7: 43559 | F7: 16.87
A8: 43476 | B8: 21.43 | C8: 43818 | D8: 12.2 | E8: 43560 | F8: 16.69
A9: 43479 | B9: 19.78 | C9: 43819 | D9: 12.07 | E9: 43563 | F9: 16.95
A10: 43480 | B10: 20.25 | C10: 43822 | D10: 12.08 | E10: 43564 | F10: 16.96
A11: 43481 | B11: 19.98 | C11: 43823 | D11: 11.99 | E11: 43565 | F11: 16.92
A12: 43482 | B12: 19.9 | C12: 43826 | D12: 11.75 | E12: 43566 | F12: 17.16
A13: 43483 | B13: 19.85 | C13: 43829 | D13: 11.73 | E13: 43567 | F13: 17.48
A14: 43486 | B14: 19.98 | C14: 43830 | D14: 11.77 | E14: 43570 | F14: 17.53
... A925: 45916 | B925: 37.44 | C925: 46021 | D925: 30.93 | E925: 45950 | F925: 29.71
A926: 45917 | B926: 37.56 | E926: 45951 | F926: 29.79
A927: 45918 | B927: 37.64 | E927: 45952 | F927: 29.77
A928: 45919 | B928: 37.61 | E928: 45953 | F928: 29.76
A929: 45922 | B929: 37.47 | E929: 45954 | F929: 29.54
A930: 45923 | B930: 37.6 | E930: 45957 | F930: 29.44
A931: 45924 | B931: 37.56 | E931: 45958 | F931: 29.44
A932: 45925 | B932: 37.45 | E932: 45960 | F932: 29.52
A933: 45926 | B933: 37.51 | E933: 45961 | F933: 29.71
A934: 45929 | B934: 37.55 | E934: 45964 | F934: 29.69
A935: 45930 | B935: 37.33 | E935: 45965 | F935: 29.78
A936: 45931 | B936: 37.02 | E936: 45966 | F936: 29.84
A937: 45932 | B937: 37.03 | E937: 45967 | F937: 29.88
... A972: 45982 | B972: 37.64 | E972: 46021 | F972: 27.1
A973: 45985 | B973: 37.63
A974: 45986 | B974: 37.48
A975: 45987 | B975: 37.3
A976: 45988 | B976: 37.22
A977: 45989 | B977: 37.11
A978: 45992 | B978: 36.89
A979: 45993 | B979: 36.8
A980: 45994 | B980: 36.45
A981: 45995 | B981: 36.38
A982: 45996 | B982: 36.36
A983: 45999 | B983: 36.35
A984: 46000 | B984: 36.43
...

Sheet Row 2
B1: =Fields!C4 -> GTNGN1YR Govt | D1: =Fields!E4 -> GTNGN5YR Govt | F1: =Fields!G4 -> GTNGN10Y Govt
B2: {=_xll.BDH(B1,FieldSpec,"1/1/2019","1/1/2026")} -> 43467 | C2: 16.978 | D2: {=_xll.BDH(D1,FieldSpec,"1/1/2019","1/1/2026")} -> 43467 | E2: 15.19 | F2: {=_xll.BDH(F1,FieldSpec,"1/1/2019","1/1/2026")} -> 43531 | G2: 14.317
B3: 43468 | C3: 16.992 | D3: 43468 | E3: 15.152 | F3: 43532 | G3: 14.357
B4: 43469 | C4: 16.941 | D4: 43483 | E4: 15.137 | F4: 43537 | G4: 14.341
B5: 43472 | C5: 16.932 | D5: 43493 | E5: 15.053 | F5: 43539 | G5: 14.272
B6: 43473 | C6: 17.161 | D6: 43497 | E6: 14.847 | F6: 43546 | G6: 14.286
B7: 43474 | C7: 17.206 | D7: 43501 | E7: 14.693 | F7: 43550 | G7: 14.348
B8: 43475 | C8: 17.121 | D8: 43502 | E8: 14.708 | F8: 43557 | G8: 14.384
B9: 43476 | C9: 17.237 | D9: 43508 | E9: 14.582 | F9: 43560 | G9: 14.758
B10: 43479 | C10: 17.116 | D10: 43509 | E10: 14.619 | F10: 43564 | G10: 14.734
B11: 43480 | C11: 17.237 | D11: 43511 | E11: 14.557 | F11: 43572 | G11: 14.596
B12: 43481 | C12: 17.193 | D12: 43514 | E12: 14.551 | F12: 43573 | G12: 14.55
B13: 43482 | C13: 17.1 | D13: 43515 | E13: 14.577 | F13: 43578 | G13: 14.54
B14: 43483 | C14: 17.061 | D14: 43518 | E14: 14.589 | F14: 43579 | G14: 14.479
... B46: 43537 | C46: 14.643 | D46: 44750 | E46: 10.748 | F46: 45762 | G46: 19.604
B47: 43538 | C47: 14.632 | D47: 44755 | E47: 11.376
B48: 43539 | C48: 14.403 | D48: 44756 | E48: 11.315
B49: 43542 | C49: 14.427 | D49: 44757 | E49: 11.45
B50: 43543 | C50: 14.381 | D50: 44775 | E50: 11.768
B51: 43544 | C51: 14.447 | D51: 44778 | E51: 11.924
B52: 43545 | C52: 14.905 | D52: 44784 | E52: 12.761
B53: 43546 | C53: 14.695 | D53: 44888 | E53: 14.557
B54: 43549 | C54: 14.793 | D54: 44889 | E54: 14.555
B55: 43550 | C55: 14.683 | D55: 45114 | E55: 13.181
B56: 43551 | C56: 14.629 | D56: 45348 | E56: 16.792
B57: 43552 | C57: 14.624
B58: 43553 | C58: 14.624
B59: 43556 | C59: 14.529
B60: 43557 | C60: 14.571
B61: 43558 | C61: 14.677
B62: 43559 | C62: 14.708
B63: 43560 | C63: 14.698
B64: 43563 | C64: 14.787
B65: 43564 | C65: 14.744
B66: 43565 | C66: 14.776
B67: 43566 | C67: 14.658
B68: 43567 | C68: 14.592
... B165: 45805 | C165: 24.084

Sheet Row 3
B1: =Fields!C5 -> GTPKR1Y Govt | D1: =Fields!E5 -> GTPKR5Y Govt | F1: =Fields!G5 -> GTPKR10Y Govt
B2: {=_xll.BDH(B1,FieldSpec,"1/1/2019","1/1/2026")} -> 44845 | C2: 15.762 | D2: {=_xll.BDH(D1,FieldSpec,"1/1/2019","1/1/2026")} -> 43607 | E2: 13.469 | F2: {=_xll.BDH(F1,FieldSpec,"1/1/2019","1/1/2026")} -> 43595 | G2: 13.22
B3: 44846 | C3: 15.772 | D3: 43683 | E3: 13.728 | F3: 43607 | G3: 13.894
B4: 44848 | C4: 15.737 | D4: 43685 | E4: 13.728 | F4: 43683 | G4: 13.483
B5: 44859 | C5: 15.737 | D5: 43774 | E5: 11.469 | F5: 43685 | G5: 13.494
B6: 44860 | C6: 15.77 | D6: 43788 | E6: 11.353 | F6: 43790 | G6: 11.418
B7: 44861 | C7: 15.766 | D7: 43789 | E7: 11.355 | F7: 43791 | G7: 11.391
B8: 44880 | C8: 15.712 | D8: 43790 | E8: 11.415 | F8: 43796 | G8: 11.356
B9: 44881 | C9: 15.768 | D9: 43802 | E9: 11.358 | F9: 43797 | G9: 11.344
B10: 44883 | C10: 15.773 | D10: 43803 | E10: 11.327 | F10: 43798 | G10: 11.354
B11: 44896 | C11: 16.915 | D11: 43804 | E11: 11.304 | F11: 43802 | G11: 11.37
B12: 44897 | C12: 16.998 | D12: 43805 | E12: 11.324 | F12: 43803 | G12: 11.317
B13: 44904 | C13: 16.925 | D13: 43809 | E13: 11.285 | F13: 43804 | G13: 11.318
B14: 44908 | C14: 16.963 | D14: 43811 | E14: 11.134 | F14: 43805 | G14: 11.303
... B54: 45751 | C54: 12.06 | D54: 44111 | E54: 9.192 | F54: 44109 | G54: 9.9
D55: 44112 | E55: 9.192 | F55: 44110 | G55: 9.919
D56: 44113 | E56: 9.35 | F56: 44111 | G56: 9.925
D57: 44116 | E57: 9.375 | F57: 44112 | G57: 9.937
D58: 44117 | E58: 9.35 | F58: 44113 | G58: 9.993
D59: 44118 | E59: 9.279 | F59: 44116 | G59: 10
D60: 44119 | E60: 9.37 | F60: 44117 | G60: 10
D61: 44120 | E61: 9.38 | F61: 44118 | G61: 9.99
D62: 44123 | E62: 9.447 | F62: 44119 | G62: 10.126
D63: 44124 | E63: 9.487 | F63: 44120 | G63: 10.265
D64: 44125 | E64: 9.475 | F64: 44123 | G64: 10.326
D65: 44126 | E65: 9.474 | F65: 44124 | G65: 10.28
D66: 44127 | E66: 9.125 | F66: 44125 | G66: 10.3
... D137: 44980 | E137: 15.952 | F137: 45377 | G137: 14.615
D138: 45013 | E138: 15.925
D139: 45321 | E139: 15.608
D140: 45334 | E140: 15.639
D141: 45335 | E141: 15.626
D142: 45336 | E142: 15.573
D143: 45350 | E143: 15.795
D144: 45351 | E144: 15.787
D145: 45365 | E145: 15.562
D146: 45377 | E146: 15.858
D147: 45379 | E147: 15.953
D148: 45380 | E148: 15.946
D149: 45405 | E149: 15.752
...

Sheet Row 4
B1: =Fields!C6 -> GTZAR1YR Govt | D1: =Fields!E6 -> GTZAR5YR Govt | F1: =Fields!G6 -> GTZAR10Y Govt
B2: {=_xll.BDH(B1,FieldSpec,"1/1/2019","1/1/2026")} -> #N/A N/A | D2: {=_xll.BDH(D1,FieldSpec,"1/1/2019","1/1/2026")} -> 43467 | E2: 8.15 | F2: {=_xll.BDH(F1,FieldSpec,"1/1/2019","1/1/2026")} -> 43479 | G2: 9.296
D3: 43468 | E3: 8.062 | F3: 43480 | G3: 9.306
D4: 43469 | E4: 8.001 | F4: 43481 | G4: 9.278
D5: 43472 | E5: 8.005 | F5: 43482 | G5: 9.307
D6: 43473 | E6: 8.052 | F6: 43483 | G6: 9.387
D7: 43474 | E7: 8.025 | F7: 43486 | G7: 9.405
D8: 43475 | E8: 7.995 | F8: 43487 | G8: 9.377
D9: 43476 | E9: 8.009 | F9: 43488 | G9: 9.346
D10: 44433 | E10: 7.331 | F10: 43489 | G10: 9.283
D11: 44434 | E11: 7.358 | F11: 43490 | G11: 9.227
D12: 44435 | E12: 7.331 | F12: 43493 | G12: 9.292
D13: 44438 | E13: 7.305 | F13: 43494 | G13: 9.281
D14: 44439 | E14: 7.315 | F14: 43495 | G14: 9.245
... D578: 46022 | E578: 7.348 | F578: 44321 | G578: 9.149
F579: 44322 | G579: 9.068
F580: 44323 | G580: 9.041
F581: 44326 | G581: 8.975
F582: 44327 | G582: 8.964
F583: 44328 | G583: 9.081
F584: 44329 | G584: 9.158
F585: 44330 | G585: 9.108
F586: 44333 | G586: 9.529
F587: 44334 | G587: 9.493
F588: 44335 | G588: 9.51
F589: 44336 | G589: 9.435
F590: 44337 | G590: 9.38
... F1742: 46022 | G1742: 8.204

Sheet Row 5
B1: =Fields!C7 -> GTBRL1Y Govt | D1: =Fields!E7 -> GTBRL5Y Govt | F1: =Fields!G7 -> GTBRL10Y Govt
B2: {=_xll.BDH(B1,FieldSpec,"1/1/2019","1/1/2026")} -> 43467 | C2: 6.7937 | D2: {=_xll.BDH(D1,FieldSpec,"1/1/2019","1/1/2026")} -> 43916 | E2: 6.8966 | F2: {=_xll.BDH(F1,FieldSpec,"1/1/2019","1/1/2026")} -> 43467 | G2: 9.2284
B3: 43468 | C3: 6.82 | D3: 43917 | E3: 6.9699 | F3: 43468 | G3: 9.1781
B4: 43469 | C4: 6.8623 | D4: 43920 | E4: 6.7855 | F4: 43469 | G4: 9.1312
B5: 43472 | C5: 6.968 | D5: 43921 | E5: 6.8541 | F5: 43472 | G5: 9.188
B6: 43473 | C6: 6.9471 | D6: 43922 | E6: 6.8641 | F6: 43473 | G6: 9.152
B7: 43474 | C7: 6.9632 | D7: 43923 | E7: 6.9356 | F7: 43474 | G7: 9.1209
B8: 43475 | C8: 7.0428 | D8: 43924 | E8: 7.2036 | F8: 43475 | G8: 9.2609
B9: 43476 | C9: 7.0166 | D9: 43927 | E9: 6.9733 | F9: 43476 | G9: 9.197
B10: 43479 | C10: 6.9727 | D10: 43928 | E10: 6.982 | F10: 43479 | G10: 9.131
B11: 43480 | C11: 7.041 | D11: 43929 | E11: 6.7337 | F11: 43480 | G11: 9.26
B12: 43481 | C12: 7.0157 | D12: 43930 | E12: 6.6379 | F12: 43481 | G12: 9.2575
B13: 43482 | C13: 6.9759 | D13: 43934 | E13: 6.5462 | F13: 43482 | G13: 9.1833
B14: 43483 | C14: 6.9217 | D14: 43935 | E14: 6.2874 | F14: 43483 | G14: 9.1
... B672: 44490 | C672: 10.3197 | D672: 46021 | E672: 13.6558 | F672: 44574 | G672: 11.3137
B673: 44491 | C673: 10.6513 | F673: 44575 | G673: 11.2887
B674: 44494 | C674: 10.9137 | F674: 44578 | G674: 11.42
B675: 44495 | C675: 11.393 | F675: 44579 | G675: 11.5937
B676: 44496 | C676: 11.1393 | F676: 44580 | G676: 11.3983
B677: 44497 | C677: 12.1498 | F677: 44581 | G677: 11.3927
B678: 44498 | C678: 12.0464 | F678: 44582 | G678: 11.5749
B679: 44501 | C679: 12.0574 | F679: 44585 | G679: 11.5333
B680: 44503 | C680: 11.7933 | F680: 44586 | G680: 11.445
B681: 44504 | C681: 11.8432 | F681: 44587 | G681: 11.515
B682: 44505 | C682: 11.8151 | F682: 44588 | G682: 11.3799
B683: 44508 | C683: 11.9706 | F683: 44589 | G683: 11.4684
B684: 44509 | C684: 11.8895 | F684: 44592 | G684: 11.3175
... B1643: 46023 | C1643: 14.1946 | F1643: 45992 | G1643: 13.3747
F1644: 45993 | G1644: 13.2688
F1645: 45994 | G1645: 13.2843
F1646: 45995 | G1646: 13.2264
F1647: 45996 | G1647: 13.7779
F1648: 45999 | G1648: 13.6991
F1649: 46000 | G1649: 13.7644
F1650: 46001 | G1650: 13.7997
F1651: 46002 | G1651: 13.7252
F1652: 46003 | G1652: 13.6396
F1653: 46006 | G1653: 13.5508
F1654: 46007 | G1654: 13.7062
F1655: 46008 | G1655: 13.902
...
